28-04-2022 18:47:00 ERROR Internal Server Error: /news/ (<class 'django.template.exceptions.TemplateDoesNotExist'>, TemplateDoesNotExist('news/idex.html, news/post_list.html'), <traceback object at 0x7f4b2472b800>) /home/andrusshka/PycharmProjects/FPW-52-D2-NewsPortal/venv/lib/python3.8/site-packages/django/utils/log.py
Traceback (most recent call last):
  File "/home/andrusshka/PycharmProjects/FPW-52-D2-NewsPortal/venv/lib/python3.8/site-packages/django/core/handlers/exception.py", line 55, in inner
    response = get_response(request)
  File "/home/andrusshka/PycharmProjects/FPW-52-D2-NewsPortal/venv/lib/python3.8/site-packages/django/core/handlers/base.py", line 220, in _get_response
    response = response.render()
  File "/home/andrusshka/PycharmProjects/FPW-52-D2-NewsPortal/venv/lib/python3.8/site-packages/django/template/response.py", line 114, in render
    self.content = self.rendered_content
  File "/home/andrusshka/PycharmProjects/FPW-52-D2-NewsPortal/venv/lib/python3.8/site-packages/django/template/response.py", line 90, in rendered_content
    template = self.resolve_template(self.template_name)
  File "/home/andrusshka/PycharmProjects/FPW-52-D2-NewsPortal/venv/lib/python3.8/site-packages/django/template/response.py", line 72, in resolve_template
    return select_template(template, using=self.using)
  File "/home/andrusshka/PycharmProjects/FPW-52-D2-NewsPortal/venv/lib/python3.8/site-packages/django/template/loader.py", line 47, in select_template
    raise TemplateDoesNotExist(", ".join(template_name_list), chain=chain)
django.template.exceptions.TemplateDoesNotExist: news/idex.html, news/post_list.html
28-04-2022 18:47:00 ERROR "GET /news/ HTTP/1.1" 500 94616 None /home/andrusshka/PycharmProjects/FPW-52-D2-NewsPortal/venv/lib/python3.8/site-packages/django/core/servers/basehttp.py
28-04-2022 18:58:58 ERROR Internal Server Error: /news/ (<class 'django.template.exceptions.TemplateDoesNotExist'>, TemplateDoesNotExist('news/inde.html, news/post_list.html'), <traceback object at 0x7fe233f80ec0>) /home/andrusshka/PycharmProjects/FPW-52-D2-NewsPortal/venv/lib/python3.8/site-packages/django/utils/log.py
Traceback (most recent call last):
  File "/home/andrusshka/PycharmProjects/FPW-52-D2-NewsPortal/venv/lib/python3.8/site-packages/django/core/handlers/exception.py", line 55, in inner
    response = get_response(request)
  File "/home/andrusshka/PycharmProjects/FPW-52-D2-NewsPortal/venv/lib/python3.8/site-packages/django/core/handlers/base.py", line 220, in _get_response
    response = response.render()
  File "/home/andrusshka/PycharmProjects/FPW-52-D2-NewsPortal/venv/lib/python3.8/site-packages/django/template/response.py", line 114, in render
    self.content = self.rendered_content
  File "/home/andrusshka/PycharmProjects/FPW-52-D2-NewsPortal/venv/lib/python3.8/site-packages/django/template/response.py", line 90, in rendered_content
    template = self.resolve_template(self.template_name)
  File "/home/andrusshka/PycharmProjects/FPW-52-D2-NewsPortal/venv/lib/python3.8/site-packages/django/template/response.py", line 72, in resolve_template
    return select_template(template, using=self.using)
  File "/home/andrusshka/PycharmProjects/FPW-52-D2-NewsPortal/venv/lib/python3.8/site-packages/django/template/loader.py", line 47, in select_template
    raise TemplateDoesNotExist(", ".join(template_name_list), chain=chain)
django.template.exceptions.TemplateDoesNotExist: news/inde.html, news/post_list.html
28-04-2022 18:58:58 ERROR "GET /news/?page=2 HTTP/1.1" 500 94964 None /home/andrusshka/PycharmProjects/FPW-52-D2-NewsPortal/venv/lib/python3.8/site-packages/django/core/servers/basehttp.py

28-04-2022 18:59:41 ERROR Internal Server Error: /news/ (<class 'django.template.exceptions.TemplateDoesNotExist'>, TemplateDoesNotExist('news/inex.html, news/post_list.html'), <traceback object at 0x7f7fec8fcb80>) /home/andrusshka/PycharmProjects/FPW-52-D2-NewsPortal/venv/lib/python3.8/site-packages/django/utils/log.py
Traceback (most recent call last):
  File "/home/andrusshka/PycharmProjects/FPW-52-D2-NewsPortal/venv/lib/python3.8/site-packages/django/core/handlers/exception.py", line 55, in inner
    response = get_response(request)
  File "/home/andrusshka/PycharmProjects/FPW-52-D2-NewsPortal/venv/lib/python3.8/site-packages/django/core/handlers/base.py", line 220, in _get_response
    response = response.render()
  File "/home/andrusshka/PycharmProjects/FPW-52-D2-NewsPortal/venv/lib/python3.8/site-packages/django/template/response.py", line 114, in render
    self.content = self.rendered_content
  File "/home/andrusshka/PycharmProjects/FPW-52-D2-NewsPortal/venv/lib/python3.8/site-packages/django/template/response.py", line 90, in rendered_content
    template = self.resolve_template(self.template_name)
  File "/home/andrusshka/PycharmProjects/FPW-52-D2-NewsPortal/venv/lib/python3.8/site-packages/django/template/response.py", line 72, in resolve_template
    return select_template(template, using=self.using)
  File "/home/andrusshka/PycharmProjects/FPW-52-D2-NewsPortal/venv/lib/python3.8/site-packages/django/template/loader.py", line 47, in select_template
    raise TemplateDoesNotExist(", ".join(template_name_list), chain=chain)
django.template.exceptions.TemplateDoesNotExist: news/inex.html, news/post_list.html
28-04-2022 18:59:41 ERROR "GET /news/?page=1 HTTP/1.1" 500 94971 None /home/andrusshka/PycharmProjects/FPW-52-D2-NewsPortal/venv/lib/python3.8/site-packages/django/core/servers/basehttp.py

28-04-2022 19:18:42 ERROR Internal Server Error: / (<class 'django.template.exceptions.TemplateDoesNotExist'>, TemplateDoesNotExist('proect/index.html'), <traceback object at 0x7fcae5914c00>) /home/andrusshka/PycharmProjects/FPW-52-D2-NewsPortal/venv/lib/python3.8/site-packages/django/utils/log.py
Traceback (most recent call last):
  File "/home/andrusshka/PycharmProjects/FPW-52-D2-NewsPortal/venv/lib/python3.8/site-packages/django/core/handlers/exception.py", line 55, in inner
    response = get_response(request)
  File "/home/andrusshka/PycharmProjects/FPW-52-D2-NewsPortal/venv/lib/python3.8/site-packages/django/core/handlers/base.py", line 220, in _get_response
    response = response.render()
  File "/home/andrusshka/PycharmProjects/FPW-52-D2-NewsPortal/venv/lib/python3.8/site-packages/django/template/response.py", line 114, in render
    self.content = self.rendered_content
  File "/home/andrusshka/PycharmProjects/FPW-52-D2-NewsPortal/venv/lib/python3.8/site-packages/django/template/response.py", line 90, in rendered_content
    template = self.resolve_template(self.template_name)
  File "/home/andrusshka/PycharmProjects/FPW-52-D2-NewsPortal/venv/lib/python3.8/site-packages/django/template/response.py", line 72, in resolve_template
    return select_template(template, using=self.using)
  File "/home/andrusshka/PycharmProjects/FPW-52-D2-NewsPortal/venv/lib/python3.8/site-packages/django/template/loader.py", line 47, in select_template
    raise TemplateDoesNotExist(", ".join(template_name_list), chain=chain)
django.template.exceptions.TemplateDoesNotExist: proect/index.html
28-04-2022 19:18:42 ERROR "GET / HTTP/1.1" 500 91667 None /home/andrusshka/PycharmProjects/FPW-52-D2-NewsPortal/venv/lib/python3.8/site-packages/django/core/servers/basehttp.py

28-04-2022 19:20:40 ERROR Internal Server Error: / (<class 'django.template.exceptions.TemplateDoesNotExist'>, TemplateDoesNotExist('proect/index.html'), <traceback object at 0x7f21eef85080>) /home/andrusshka/PycharmProjects/FPW-52-D2-NewsPortal/venv/lib/python3.8/site-packages/django/utils/log.py
Traceback (most recent call last):
  File "/home/andrusshka/PycharmProjects/FPW-52-D2-NewsPortal/venv/lib/python3.8/site-packages/django/core/handlers/exception.py", line 55, in inner
    response = get_response(request)
  File "/home/andrusshka/PycharmProjects/FPW-52-D2-NewsPortal/venv/lib/python3.8/site-packages/django/core/handlers/base.py", line 220, in _get_response
    response = response.render()
  File "/home/andrusshka/PycharmProjects/FPW-52-D2-NewsPortal/venv/lib/python3.8/site-packages/django/template/response.py", line 114, in render
    self.content = self.rendered_content
  File "/home/andrusshka/PycharmProjects/FPW-52-D2-NewsPortal/venv/lib/python3.8/site-packages/django/template/response.py", line 90, in rendered_content
    template = self.resolve_template(self.template_name)
  File "/home/andrusshka/PycharmProjects/FPW-52-D2-NewsPortal/venv/lib/python3.8/site-packages/django/template/response.py", line 72, in resolve_template
    return select_template(template, using=self.using)
  File "/home/andrusshka/PycharmProjects/FPW-52-D2-NewsPortal/venv/lib/python3.8/site-packages/django/template/loader.py", line 47, in select_template
    raise TemplateDoesNotExist(", ".join(template_name_list), chain=chain)
django.template.exceptions.TemplateDoesNotExist: proect/index.html
28-04-2022 19:20:40 ERROR "GET / HTTP/1.1" 500 91720 None /home/andrusshka/PycharmProjects/FPW-52-D2-NewsPortal/venv/lib/python3.8/site-packages/django/core/servers/basehttp.py

28-04-2022 19:22:09 ERROR Internal Server Error: / (<class 'django.template.exceptions.TemplateDoesNotExist'>, TemplateDoesNotExist('proect/index.html'), <traceback object at 0x7f2b26e25e80>) /home/andrusshka/PycharmProjects/FPW-52-D2-NewsPortal/venv/lib/python3.8/site-packages/django/utils/log.py
Traceback (most recent call last):
  File "/home/andrusshka/PycharmProjects/FPW-52-D2-NewsPortal/venv/lib/python3.8/site-packages/django/core/handlers/exception.py", line 55, in inner
    response = get_response(request)
  File "/home/andrusshka/PycharmProjects/FPW-52-D2-NewsPortal/venv/lib/python3.8/site-packages/django/core/handlers/base.py", line 220, in _get_response
    response = response.render()
  File "/home/andrusshka/PycharmProjects/FPW-52-D2-NewsPortal/venv/lib/python3.8/site-packages/django/template/response.py", line 114, in render
    self.content = self.rendered_content
  File "/home/andrusshka/PycharmProjects/FPW-52-D2-NewsPortal/venv/lib/python3.8/site-packages/django/template/response.py", line 90, in rendered_content
    template = self.resolve_template(self.template_name)
  File "/home/andrusshka/PycharmProjects/FPW-52-D2-NewsPortal/venv/lib/python3.8/site-packages/django/template/response.py", line 72, in resolve_template
    return select_template(template, using=self.using)
  File "/home/andrusshka/PycharmProjects/FPW-52-D2-NewsPortal/venv/lib/python3.8/site-packages/django/template/loader.py", line 47, in select_template
    raise TemplateDoesNotExist(", ".join(template_name_list), chain=chain)
django.template.exceptions.TemplateDoesNotExist: proect/index.html
28-04-2022 19:22:09 ERROR "GET / HTTP/1.1" 500 91719 None /home/andrusshka/PycharmProjects/FPW-52-D2-NewsPortal/venv/lib/python3.8/site-packages/django/core/servers/basehttp.py

29-04-2022 07:58:03 ERROR Internal Server Error: /accounts/google/login/ (<class 'allauth.socialaccount.models.SocialApp.DoesNotExist'>, DoesNotExist('SocialApp matching query does not exist.'), <traceback object at 0x7f4c6e625d40>) /home/andrusshka/PycharmProjects/FPW-52-D2-NewsPortal/venv/lib/python3.8/site-packages/django/utils/log.py
Traceback (most recent call last):
  File "/home/andrusshka/PycharmProjects/FPW-52-D2-NewsPortal/venv/lib/python3.8/site-packages/django/core/handlers/exception.py", line 55, in inner
    response = get_response(request)
  File "/home/andrusshka/PycharmProjects/FPW-52-D2-NewsPortal/venv/lib/python3.8/site-packages/django/core/handlers/base.py", line 197, in _get_response
    response = wrapped_callback(request, *callback_args, **callback_kwargs)
  File "/home/andrusshka/PycharmProjects/FPW-52-D2-NewsPortal/venv/lib/python3.8/site-packages/allauth/socialaccount/providers/oauth2/views.py", line 80, in view
    return self.dispatch(request, *args, **kwargs)
  File "/home/andrusshka/PycharmProjects/FPW-52-D2-NewsPortal/venv/lib/python3.8/site-packages/allauth/socialaccount/providers/base/mixins.py", line 18, in dispatch
    return self.login(request, *args, **kwargs)
  File "/home/andrusshka/PycharmProjects/FPW-52-D2-NewsPortal/venv/lib/python3.8/site-packages/allauth/socialaccount/providers/oauth2/views.py", line 108, in login
    app = provider.get_app(self.request)
  File "/home/andrusshka/PycharmProjects/FPW-52-D2-NewsPortal/venv/lib/python3.8/site-packages/allauth/socialaccount/providers/base/provider.py", line 30, in get_app
    return adapter.get_app(request, self.id)
  File "/home/andrusshka/PycharmProjects/FPW-52-D2-NewsPortal/venv/lib/python3.8/site-packages/allauth/socialaccount/adapter.py", line 204, in get_app
    app = SocialApp.objects.get_current(provider, request)
  File "/home/andrusshka/PycharmProjects/FPW-52-D2-NewsPortal/venv/lib/python3.8/site-packages/allauth/socialaccount/models.py", line 32, in get_current
    app = self.get(sites__id=site.id, provider=provider)
  File "/home/andrusshka/PycharmProjects/FPW-52-D2-NewsPortal/venv/lib/python3.8/site-packages/django/db/models/manager.py", line 85, in manager_method
    return getattr(self.get_queryset(), name)(*args, **kwargs)
  File "/home/andrusshka/PycharmProjects/FPW-52-D2-NewsPortal/venv/lib/python3.8/site-packages/django/db/models/query.py", line 496, in get
    raise self.model.DoesNotExist(
allauth.socialaccount.models.SocialApp.DoesNotExist: SocialApp matching query does not exist.
29-04-2022 07:58:03 ERROR "POST /accounts/google/login/?process=login HTTP/1.1" 500 108538 None /home/andrusshka/PycharmProjects/FPW-52-D2-NewsPortal/venv/lib/python3.8/site-packages/django/core/servers/basehttp.py

29-04-2022 08:07:27 ERROR Internal Server Error: /accounts/google/login/ (<class 'allauth.socialaccount.models.SocialApp.DoesNotExist'>, DoesNotExist('SocialApp matching query does not exist.'), <traceback object at 0x7f16a1b5f6c0>) /home/andrusshka/PycharmProjects/FPW-52-D2-NewsPortal/venv/lib/python3.8/site-packages/django/utils/log.py
Traceback (most recent call last):
  File "/home/andrusshka/PycharmProjects/FPW-52-D2-NewsPortal/venv/lib/python3.8/site-packages/django/core/handlers/exception.py", line 55, in inner
    response = get_response(request)
  File "/home/andrusshka/PycharmProjects/FPW-52-D2-NewsPortal/venv/lib/python3.8/site-packages/django/core/handlers/base.py", line 197, in _get_response
    response = wrapped_callback(request, *callback_args, **callback_kwargs)
  File "/home/andrusshka/PycharmProjects/FPW-52-D2-NewsPortal/venv/lib/python3.8/site-packages/allauth/socialaccount/providers/oauth2/views.py", line 80, in view
    return self.dispatch(request, *args, **kwargs)
  File "/home/andrusshka/PycharmProjects/FPW-52-D2-NewsPortal/venv/lib/python3.8/site-packages/allauth/socialaccount/providers/base/mixins.py", line 18, in dispatch
    return self.login(request, *args, **kwargs)
  File "/home/andrusshka/PycharmProjects/FPW-52-D2-NewsPortal/venv/lib/python3.8/site-packages/allauth/socialaccount/providers/oauth2/views.py", line 108, in login
    app = provider.get_app(self.request)
  File "/home/andrusshka/PycharmProjects/FPW-52-D2-NewsPortal/venv/lib/python3.8/site-packages/allauth/socialaccount/providers/base/provider.py", line 30, in get_app
    return adapter.get_app(request, self.id)
  File "/home/andrusshka/PycharmProjects/FPW-52-D2-NewsPortal/venv/lib/python3.8/site-packages/allauth/socialaccount/adapter.py", line 204, in get_app
    app = SocialApp.objects.get_current(provider, request)
  File "/home/andrusshka/PycharmProjects/FPW-52-D2-NewsPortal/venv/lib/python3.8/site-packages/allauth/socialaccount/models.py", line 32, in get_current
    app = self.get(sites__id=site.id, provider=provider)
  File "/home/andrusshka/PycharmProjects/FPW-52-D2-NewsPortal/venv/lib/python3.8/site-packages/django/db/models/manager.py", line 85, in manager_method
    return getattr(self.get_queryset(), name)(*args, **kwargs)
  File "/home/andrusshka/PycharmProjects/FPW-52-D2-NewsPortal/venv/lib/python3.8/site-packages/django/db/models/query.py", line 496, in get
    raise self.model.DoesNotExist(
allauth.socialaccount.models.SocialApp.DoesNotExist: SocialApp matching query does not exist.
29-04-2022 08:07:27 ERROR "POST /accounts/google/login/?process=login HTTP/1.1" 500 108456 None /home/andrusshka/PycharmProjects/FPW-52-D2-NewsPortal/venv/lib/python3.8/site-packages/django/core/servers/basehttp.py

29-04-2022 08:09:26 ERROR Internal Server Error: /accounts/google/login/ (<class 'allauth.socialaccount.models.SocialApp.DoesNotExist'>, DoesNotExist('SocialApp matching query does not exist.'), <traceback object at 0x7f6961413180>) /home/andrusshka/PycharmProjects/FPW-52-D2-NewsPortal/venv/lib/python3.8/site-packages/django/utils/log.py
Traceback (most recent call last):
  File "/home/andrusshka/PycharmProjects/FPW-52-D2-NewsPortal/venv/lib/python3.8/site-packages/django/core/handlers/exception.py", line 55, in inner
    response = get_response(request)
  File "/home/andrusshka/PycharmProjects/FPW-52-D2-NewsPortal/venv/lib/python3.8/site-packages/django/core/handlers/base.py", line 197, in _get_response
    response = wrapped_callback(request, *callback_args, **callback_kwargs)
  File "/home/andrusshka/PycharmProjects/FPW-52-D2-NewsPortal/venv/lib/python3.8/site-packages/allauth/socialaccount/providers/oauth2/views.py", line 80, in view
    return self.dispatch(request, *args, **kwargs)
  File "/home/andrusshka/PycharmProjects/FPW-52-D2-NewsPortal/venv/lib/python3.8/site-packages/allauth/socialaccount/providers/base/mixins.py", line 18, in dispatch
    return self.login(request, *args, **kwargs)
  File "/home/andrusshka/PycharmProjects/FPW-52-D2-NewsPortal/venv/lib/python3.8/site-packages/allauth/socialaccount/providers/oauth2/views.py", line 108, in login
    app = provider.get_app(self.request)
  File "/home/andrusshka/PycharmProjects/FPW-52-D2-NewsPortal/venv/lib/python3.8/site-packages/allauth/socialaccount/providers/base/provider.py", line 30, in get_app
    return adapter.get_app(request, self.id)
  File "/home/andrusshka/PycharmProjects/FPW-52-D2-NewsPortal/venv/lib/python3.8/site-packages/allauth/socialaccount/adapter.py", line 204, in get_app
    app = SocialApp.objects.get_current(provider, request)
  File "/home/andrusshka/PycharmProjects/FPW-52-D2-NewsPortal/venv/lib/python3.8/site-packages/allauth/socialaccount/models.py", line 32, in get_current
    app = self.get(sites__id=site.id, provider=provider)
  File "/home/andrusshka/PycharmProjects/FPW-52-D2-NewsPortal/venv/lib/python3.8/site-packages/django/db/models/manager.py", line 85, in manager_method
    return getattr(self.get_queryset(), name)(*args, **kwargs)
  File "/home/andrusshka/PycharmProjects/FPW-52-D2-NewsPortal/venv/lib/python3.8/site-packages/django/db/models/query.py", line 496, in get
    raise self.model.DoesNotExist(
allauth.socialaccount.models.SocialApp.DoesNotExist: SocialApp matching query does not exist.
29-04-2022 08:09:26 ERROR "POST /accounts/google/login/?process=login HTTP/1.1" 500 108455 None /home/andrusshka/PycharmProjects/FPW-52-D2-NewsPortal/venv/lib/python3.8/site-packages/django/core/servers/basehttp.py

29-04-2022 12:31:15 ERROR Internal Server Error: /accounts/google/login/ (<class 'allauth.socialaccount.models.SocialApp.DoesNotExist'>, DoesNotExist('SocialApp matching query does not exist.'), <traceback object at 0x7fa42572e300>) /home/andrusshka/PycharmProjects/FPW-52-D2-NewsPortal/venv/lib/python3.8/site-packages/django/utils/log.py
Traceback (most recent call last):
  File "/home/andrusshka/PycharmProjects/FPW-52-D2-NewsPortal/venv/lib/python3.8/site-packages/django/core/handlers/exception.py", line 55, in inner
    response = get_response(request)
  File "/home/andrusshka/PycharmProjects/FPW-52-D2-NewsPortal/venv/lib/python3.8/site-packages/django/core/handlers/base.py", line 197, in _get_response
    response = wrapped_callback(request, *callback_args, **callback_kwargs)
  File "/home/andrusshka/PycharmProjects/FPW-52-D2-NewsPortal/venv/lib/python3.8/site-packages/allauth/socialaccount/providers/oauth2/views.py", line 80, in view
    return self.dispatch(request, *args, **kwargs)
  File "/home/andrusshka/PycharmProjects/FPW-52-D2-NewsPortal/venv/lib/python3.8/site-packages/allauth/socialaccount/providers/base/mixins.py", line 18, in dispatch
    return self.login(request, *args, **kwargs)
  File "/home/andrusshka/PycharmProjects/FPW-52-D2-NewsPortal/venv/lib/python3.8/site-packages/allauth/socialaccount/providers/oauth2/views.py", line 108, in login
    app = provider.get_app(self.request)
  File "/home/andrusshka/PycharmProjects/FPW-52-D2-NewsPortal/venv/lib/python3.8/site-packages/allauth/socialaccount/providers/base/provider.py", line 30, in get_app
    return adapter.get_app(request, self.id)
  File "/home/andrusshka/PycharmProjects/FPW-52-D2-NewsPortal/venv/lib/python3.8/site-packages/allauth/socialaccount/adapter.py", line 204, in get_app
    app = SocialApp.objects.get_current(provider, request)
  File "/home/andrusshka/PycharmProjects/FPW-52-D2-NewsPortal/venv/lib/python3.8/site-packages/allauth/socialaccount/models.py", line 32, in get_current
    app = self.get(sites__id=site.id, provider=provider)
  File "/home/andrusshka/PycharmProjects/FPW-52-D2-NewsPortal/venv/lib/python3.8/site-packages/django/db/models/manager.py", line 85, in manager_method
    return getattr(self.get_queryset(), name)(*args, **kwargs)
  File "/home/andrusshka/PycharmProjects/FPW-52-D2-NewsPortal/venv/lib/python3.8/site-packages/django/db/models/query.py", line 496, in get
    raise self.model.DoesNotExist(
allauth.socialaccount.models.SocialApp.DoesNotExist: SocialApp matching query does not exist.
